Traceback (most recent call last):
  File "/Users/curtislu/Library/Caches/pypoetry/virtualenvs/ntu-ps-intro-ml-GyDE60mE-py3.11/lib/python3.11/site-packages/jupyter_cache/executors/utils.py", line 58, in single_nb_execution
    executenb(
  File "/Users/curtislu/Library/Caches/pypoetry/virtualenvs/ntu-ps-intro-ml-GyDE60mE-py3.11/lib/python3.11/site-packages/nbclient/client.py", line 1305, in execute
    return NotebookClient(nb=nb, resources=resources, km=km, **kwargs).execute()
           ^^^^^^^^^^^^^^^^^^^^^^^^^^^^^^^^^^^^^^^^^^^^^^^^^^^^^^^^^^^^^^^^^^^^^
  File "/Users/curtislu/Library/Caches/pypoetry/virtualenvs/ntu-ps-intro-ml-GyDE60mE-py3.11/lib/python3.11/site-packages/jupyter_core/utils/__init__.py", line 173, in wrapped
    return loop.run_until_complete(inner)
           ^^^^^^^^^^^^^^^^^^^^^^^^^^^^^^
  File "/Users/curtislu/.pyenv/versions/3.11.0/lib/python3.11/asyncio/base_events.py", line 650, in run_until_complete
    return future.result()
           ^^^^^^^^^^^^^^^
  File "/Users/curtislu/.pyenv/versions/3.11.0/lib/python3.11/contextlib.py", line 222, in __aexit__
    await self.gen.athrow(typ, value, traceback)
  File "/Users/curtislu/Library/Caches/pypoetry/virtualenvs/ntu-ps-intro-ml-GyDE60mE-py3.11/lib/python3.11/site-packages/nbclient/client.py", line 650, in async_setup_kernel
    yield
  File "/Users/curtislu/Library/Caches/pypoetry/virtualenvs/ntu-ps-intro-ml-GyDE60mE-py3.11/lib/python3.11/site-packages/nbclient/client.py", line 705, in async_execute
    await self.async_execute_cell(
  File "/Users/curtislu/Library/Caches/pypoetry/virtualenvs/ntu-ps-intro-ml-GyDE60mE-py3.11/lib/python3.11/site-packages/nbclient/client.py", line 1058, in async_execute_cell
    await self._check_raise_for_error(cell, cell_index, exec_reply)
  File "/Users/curtislu/Library/Caches/pypoetry/virtualenvs/ntu-ps-intro-ml-GyDE60mE-py3.11/lib/python3.11/site-packages/nbclient/client.py", line 914, in _check_raise_for_error
    raise CellExecutionError.from_cell_and_msg(cell, exec_reply_content)
nbclient.exceptions.CellExecutionError: An error occurred while executing the following cell:
------------------
a_list = ['a','b','c']
print(a_list[0])
print(a_list[-1])
print(a_list[1:])
print(a_list[0:1])
print(a_list[3])
print(a_list[::-1])

a_list = ['a', 'b', 'c', [1, 2, 3]]
a_list[3][2]
------------------

----- stdout -----
a
c
['b', 'c']
['a']
------------------

[0;31m---------------------------------------------------------------------------[0m
[0;31mIndexError[0m                                Traceback (most recent call last)
Cell [0;32mIn[3], line 6[0m
[1;32m      4[0m [38;5;28mprint[39m(a_list[[38;5;241m1[39m:])
[1;32m      5[0m [38;5;28mprint[39m(a_list[[38;5;241m0[39m:[38;5;241m1[39m])
[0;32m----> 6[0m [38;5;28mprint[39m([43ma_list[49m[43m[[49m[38;5;241;43m3[39;49m[43m][49m)
[1;32m      7[0m [38;5;28mprint[39m(a_list[::[38;5;241m-[39m[38;5;241m1[39m])
[1;32m      9[0m a_list [38;5;241m=[39m [[38;5;124m'[39m[38;5;124ma[39m[38;5;124m'[39m, [38;5;124m'[39m[38;5;124mb[39m[38;5;124m'[39m, [38;5;124m'[39m[38;5;124mc[39m[38;5;124m'[39m, [[38;5;241m1[39m, [38;5;241m2[39m, [38;5;241m3[39m]]

[0;31mIndexError[0m: list index out of range

